Workbook
Name Slicer_Category: #N/A
Name Slicer_Date_Year: #N/A

Sheet Sales_Table
A1: Date | B1: Order_id | C1: Product_id | D1: Cost Price | E1: Selling Price | F1: Quantity_Sold | G1: Total_Sale | H1: Mode of Payment | I1: Profit | J1: Date(Year) | K1: Date(Month)
A2: 10/02/2023 | B2: O2001 | C2: P101 | D2: =IF(C2="P101",271,IF(C2="P102",408,IF(C2="P103",735,IF(C2="P104",749,IF(C2="P105",807,IF(C2="P106",365,IF(C2="P107",213,IF(C2="P108",117,IF(C2="P109",399,IF(C2="P110",520,IF(C2="P111",505,IF(C2="P112",380,IF(C2="P113",392,IF(C2="P114",164,IF(C2="P115",282,IF(C2="P116",386,IF(C2="P117",217,IF(C2="P118",518,IF(C2="P119",321,IF(C2="P120",593,IF(C2="P121",104,0))))))))))))))))))))) -> 271 | E2: 476 | F2: 3 | G2: =Sales_Table!$E2*F2 -> 1428 | H2: COD | I2: =G2-(D2*F2) -> 615 | J2: =YEAR(Table16[[#This Row],[Date]]) -> 2023 | K2: =TEXT(Table16[[#This Row],[Date]],"MMMM") -> February
A3: 18/09/2024 | B3: O2002 | C3: P101 | D3: =IF(C3="P101",271,IF(C3="P102",408,IF(C3="P103",735,IF(C3="P104",749,IF(C3="P105",807,IF(C3="P106",365,IF(C3="P107",213,IF(C3="P108",117,IF(C3="P109",399,IF(C3="P110",520,IF(C3="P111",505,IF(C3="P112",380,IF(C3="P113",392,IF(C3="P114",164,IF(C3="P115",282,IF(C3="P116",386,IF(C3="P117",217,IF(C3="P118",518,IF(C3="P119",321,IF(C3="P120",593,IF(C3="P121",104,0))))))))))))))))))))) -> 271 | E3: 476 | F3: 3 | G3: =Sales_Table!$E3*F3 -> 1428 | H3: COD | I3: =G3-(D3*F3) -> 615 | J3: =YEAR(Table16[[#This Row],[Date]]) -> 2024 | K3: =TEXT(Table16[[#This Row],[Date]],"MMMM") -> September
A4: 09/07/2020 | B4: O2003 | C4: P101 | D4: =IF(C4="P101",271,IF(C4="P102",408,IF(C4="P103",735,IF(C4="P104",749,IF(C4="P105",807,IF(C4="P106",365,IF(C4="P107",213,IF(C4="P108",117,IF(C4="P109",399,IF(C4="P110",520,IF(C4="P111",505,IF(C4="P112",380,IF(C4="P113",392,IF(C4="P114",164,IF(C4="P115",282,IF(C4="P116",386,IF(C4="P117",217,IF(C4="P118",518,IF(C4="P119",321,IF(C4="P120",593,IF(C4="P121",104,0))))))))))))))))))))) -> 271 | E4: 476 | F4: 7 | G4: =Sales_Table!$E4*F4 -> 3332 | H4: COD | I4: =G4-(D4*F4) -> 1435 | J4: =YEAR(Table16[[#This Row],[Date]]) -> 2020 | K4: =TEXT(Table16[[#This Row],[Date]],"MMMM") -> July
A5: 30/07/2022 | B5: O2004 | C5: P101 | D5: =IF(C5="P101",271,IF(C5="P102",408,IF(C5="P103",735,IF(C5="P104",749,IF(C5="P105",807,IF(C5="P106",365,IF(C5="P107",213,IF(C5="P108",117,IF(C5="P109",399,IF(C5="P110",520,IF(C5="P111",505,IF(C5="P112",380,IF(C5="P113",392,IF(C5="P114",164,IF(C5="P115",282,IF(C5="P116",386,IF(C5="P117",217,IF(C5="P118",518,IF(C5="P119",321,IF(C5="P120",593,IF(C5="P121",104,0))))))))))))))))))))) -> 271 | E5: 476 | F5: 8 | G5: =Sales_Table!$E5*F5 -> 3808 | H5: COD | I5: =G5-(D5*F5) -> 1640 | J5: =YEAR(Table16[[#This Row],[Date]]) -> 2022 | K5: =TEXT(Table16[[#This Row],[Date]],"MMMM") -> July
A6: 10/01/2020 | B6: O2005 | C6: P101 | D6: =IF(C6="P101",271,IF(C6="P102",408,IF(C6="P103",735,IF(C6="P104",749,IF(C6="P105",807,IF(C6="P106",365,IF(C6="P107",213,IF(C6="P108",117,IF(C6="P109",399,IF(C6="P110",520,IF(C6="P111",505,IF(C6="P112",380,IF(C6="P113",392,IF(C6="P114",164,IF(C6="P115",282,IF(C6="P116",386,IF(C6="P117",217,IF(C6="P118",518,IF(C6="P119",321,IF(C6="P120",593,IF(C6="P121",104,0))))))))))))))))))))) -> 271 | E6: 476 | F6: 5 | G6: =Sales_Table!$E6*F6 -> 2380 | H6: Credit | I6: =G6-(D6*F6) -> 1025 | J6: =YEAR(Table16[[#This Row],[Date]]) -> 2020 | K6: =TEXT(Table16[[#This Row],[Date]],"MMMM") -> January
A7: 29/03/2021 | B7: O2006 | C7: P101 | D7: =IF(C7="P101",271,IF(C7="P102",408,IF(C7="P103",735,IF(C7="P104",749,IF(C7="P105",807,IF(C7="P106",365,IF(C7="P107",213,IF(C7="P108",117,IF(C7="P109",399,IF(C7="P110",520,IF(C7="P111",505,IF(C7="P112",380,IF(C7="P113",392,IF(C7="P114",164,IF(C7="P115",282,IF(C7="P116",386,IF(C7="P117",217,IF(C7="P118",518,IF(C7="P119",321,IF(C7="P120",593,IF(C7="P121",104,0))))))))))))))))))))) -> 271 | E7: 476 | F7: 1 | G7: =Sales_Table!$E7*F7 -> 476 | H7: EMI | I7: =G7-(D7*F7) -> 205 | J7: =YEAR(Table16[[#This Row],[Date]]) -> 2021 | K7: =TEXT(Table16[[#This Row],[Date]],"MMMM") -> March
A8: 21/10/2023 | B8: O2007 | C8: P101 | D8: =IF(C8="P101",271,IF(C8="P102",408,IF(C8="P103",735,IF(C8="P104",749,IF(C8="P105",807,IF(C8="P106",365,IF(C8="P107",213,IF(C8="P108",117,IF(C8="P109",399,IF(C8="P110",520,IF(C8="P111",505,IF(C8="P112",380,IF(C8="P113",392,IF(C8="P114",164,IF(C8="P115",282,IF(C8="P116",386,IF(C8="P117",217,IF(C8="P118",518,IF(C8="P119",321,IF(C8="P120",593,IF(C8="P121",104,0))))))))))))))))))))) -> 271 | E8: 476 | F8: 7 | G8: =Sales_Table!$E8*F8 -> 3332 | H8: COD | I8: =G8-(D8*F8) -> 1435 | J8: =YEAR(Table16[[#This Row],[Date]]) -> 2023 | K8: =TEXT(Table16[[#This Row],[Date]],"MMMM") -> October
A9: 25/05/2025 | B9: O2008 | C9: P101 | D9: =IF(C9="P101",271,IF(C9="P102",408,IF(C9="P103",735,IF(C9="P104",749,IF(C9="P105",807,IF(C9="P106",365,IF(C9="P107",213,IF(C9="P108",117,IF(C9="P109",399,IF(C9="P110",520,IF(C9="P111",505,IF(C9="P112",380,IF(C9="P113",392,IF(C9="P114",164,IF(C9="P115",282,IF(C9="P116",386,IF(C9="P117",217,IF(C9="P118",518,IF(C9="P119",321,IF(C9="P120",593,IF(C9="P121",104,0))))))))))))))))))))) -> 271 | E9: 476 | F9: 2 | G9: =Sales_Table!$E9*F9 -> 952 | H9: Debit | I9: =G9-(D9*F9) -> 410 | J9: =YEAR(Table16[[#This Row],[Date]]) -> 2025 | K9: =TEXT(Table16[[#This Row],[Date]],"MMMM") -> May
A10: 13/12/2020 | B10: O2009 | C10: P101 | D10: =IF(C10="P101",271,IF(C10="P102",408,IF(C10="P103",735,IF(C10="P104",749,IF(C10="P105",807,IF(C10="P106",365,IF(C10="P107",213,IF(C10="P108",117,IF(C10="P109",399,IF(C10="P110",520,IF(C10="P111",505,IF(C10="P112",380,IF(C10="P113",392,IF(C10="P114",164,IF(C10="P115",282,IF(C10="P116",386,IF(C10="P117",217,IF(C10="P118",518,IF(C10="P119",321,IF(C10="P120",593,IF(C10="P121",104,0))))))))))))))))))))) -> 271 | E10: 476 | F10: 1 | G10: =Sales_Table!$E10*F10 -> 476 | H10: EMI | I10: =G10-(D10*F10) -> 205 | J10: =YEAR(Table16[[#This Row],[Date]]) -> 2020 | K10: =TEXT(Table16[[#This Row],[Date]],"MMMM") -> December
A11: 15/04/2023 | B11: O2010 | C11: P101 | D11: =IF(C11="P101",271,IF(C11="P102",408,IF(C11="P103",735,IF(C11="P104",749,IF(C11="P105",807,IF(C11="P106",365,IF(C11="P107",213,IF(C11="P108",117,IF(C11="P109",399,IF(C11="P110",520,IF(C11="P111",505,IF(C11="P112",380,IF(C11="P113",392,IF(C11="P114",164,IF(C11="P115",282,IF(C11="P116",386,IF(C11="P117",217,IF(C11="P118",518,IF(C11="P119",321,IF(C11="P120",593,IF(C11="P121",104,0))))))))))))))))))))) -> 271 | E11: 476 | F11: 1 | G11: =Sales_Table!$E11*F11 -> 476 | H11: COD | I11: =G11-(D11*F11) -> 205 | J11: =YEAR(Table16[[#This Row],[Date]]) -> 2023 | K11: =TEXT(Table16[[#This Row],[Date]],"MMMM") -> April
A12: 23/05/2020 | B12: O2011 | C12: P101 | D12: =IF(C12="P101",271,IF(C12="P102",408,IF(C12="P103",735,IF(C12="P104",749,IF(C12="P105",807,IF(C12="P106",365,IF(C12="P107",213,IF(C12="P108",117,IF(C12="P109",399,IF(C12="P110",520,IF(C12="P111",505,IF(C12="P112",380,IF(C12="P113",392,IF(C12="P114",164,IF(C12="P115",282,IF(C12="P116",386,IF(C12="P117",217,IF(C12="P118",518,IF(C12="P119",321,IF(C12="P120",593,IF(C12="P121",104,0))))))))))))))))))))) -> 271 | E12: 476 | F12: 3 | G12: =Sales_Table!$E12*F12 -> 1428 | H12: COD | I12: =G12-(D12*F12) -> 615 | J12: =YEAR(Table16[[#This Row],[Date]]) -> 2020 | K12: =TEXT(Table16[[#This Row],[Date]],"MMMM") -> May
A13: 09/06/2021 | B13: O2012 | C13: P101 | D13: =IF(C13="P101",271,IF(C13="P102",408,IF(C13="P103",735,IF(C13="P104",749,IF(C13="P105",807,IF(C13="P106",365,IF(C13="P107",213,IF(C13="P108",117,IF(C13="P109",399,IF(C13="P110",520,IF(C13="P111",505,IF(C13="P112",380,IF(C13="P113",392,IF(C13="P114",164,IF(C13="P115",282,IF(C13="P116",386,IF(C13="P117",217,IF(C13="P118",518,IF(C13="P119",321,IF(C13="P120",593,IF(C13="P121",104,0))))))))))))))))))))) -> 271 | E13: 476 | F13: 4 | G13: =Sales_Table!$E13*F13 -> 1904 | H13: Credit | I13: =G13-(D13*F13) -> 820 | J13: =YEAR(Table16[[#This Row],[Date]]) -> 2021 | K13: =TEXT(Table16[[#This Row],[Date]],"MMMM") -> June
... A399: 02/10/2022 | B399: O2398 | C399: P121 | D399: =IF(C399="P101",271,IF(C399="P102",408,IF(C399="P103",735,IF(C399="P104",749,IF(C399="P105",807,IF(C399="P106",365,IF(C399="P107",213,IF(C399="P108",117,IF(C399="P109",399,IF(C399="P110",520,IF(C399="P111",505,IF(C399="P112",380,IF(C399="P113",392,IF(C399="P114",164,IF(C399="P115",282,IF(C399="P116",386,IF(C399="P117",217,IF(C399="P118",518,IF(C399="P119",321,IF(C399="P120",593,IF(C399="P121",104,0))))))))))))))))))))) -> 104 | E399: 130 | F399: 8 | G399: =Sales_Table!$E399*F399 -> 1040 | H399: EMI | I399: =G399-(D399*F399) -> 208 | J399: =YEAR(Table16[[#This Row],[Date]]) -> 2022 | K399: =TEXT(Table16[[#This Row],[Date]],"MMMM") -> October
A400: 19/08/2022 | B400: O2399 | C400: P122 | D400: =IF(C401="P122",183,IF(C401="P123",371,IF(C401="P124",415,IF(C401="P125",508,IF(C401="P126",358,IF(C401="P127",712,IF(C401="P128",126,IF(C401="P129",280,IF(C401="P130",695,IF(C401="P131",216,IF(C401="P132",540,IF(C401="P133",181,IF(C401="P134",353,IF(C401="P135",226,IF(C401="P136",604,IF(C401="P137",97,IF(C401="P138",465,IF(C401="P139",637,IF(C401="P140",307,0))))))))))))))))))) -> 183 | E400: 155 | F400: 3 | G400: =Sales_Table!$E400*F400 -> 465 | H400: EMI | I400: =G400-(D400*F400) -> -84 | J400: =YEAR(Table16[[#This Row],[Date]]) -> 2022 | K400: =TEXT(Table16[[#This Row],[Date]],"MMMM") -> August
A401: 01/07/2020 | B401: O2400 | C401: P122 | D401: =IF(C401="P122",183,IF(C401="P123",371,IF(C401="P124",415,IF(C401="P125",508,IF(C401="P126",358,IF(C401="P127",712,IF(C401="P128",126,IF(C401="P129",280,IF(C401="P130",695,IF(C401="P131",216,IF(C401="P132",540,IF(C401="P133",181,IF(C401="P134",353,IF(C401="P135",226,IF(C401="P136",604,IF(C401="P137",97,IF(C401="P138",465,IF(C401="P139",637,IF(C401="P140",307,0))))))))))))))))))) -> 183 | E401: 155 | F401: 10 | G401: =Sales_Table!$E401*F401 -> 1550 | H401: COD | I401: =G401-(D401*F401) -> -280 | J401: =YEAR(Table16[[#This Row],[Date]]) -> 2020 | K401: =TEXT(Table16[[#This Row],[Date]],"MMMM") -> July
A402: 25/02/2025 | B402: O2401 | C402: P122 | D402: =IF(C402="P122",183,IF(C402="P123",371,IF(C402="P124",415,IF(C402="P125",508,IF(C402="P126",358,IF(C402="P127",712,IF(C402="P128",126,IF(C402="P129",280,IF(C402="P130",695,IF(C402="P131",216,IF(C402="P132",540,IF(C402="P133",181,IF(C402="P134",353,IF(C402="P135",226,IF(C402="P136",604,IF(C402="P137",97,IF(C402="P138",465,IF(C402="P139",637,IF(C402="P140",307,0))))))))))))))))))) -> 183 | E402: 155 | F402: 4 | G402: =Sales_Table!$E402*F402 -> 620 | H402: Debit | I402: =G402-(D402*F402) -> -112 | J402: =YEAR(Table16[[#This Row],[Date]]) -> 2025 | K402: =TEXT(Table16[[#This Row],[Date]],"MMMM") -> February
A403: 20/04/2022 | B403: O2402 | C403: P122 | D403: =IF(C403="P122",183,IF(C403="P123",371,IF(C403="P124",415,IF(C403="P125",508,IF(C403="P126",358,IF(C403="P127",712,IF(C403="P128",126,IF(C403="P129",280,IF(C403="P130",695,IF(C403="P131",216,IF(C403="P132",540,IF(C403="P133",181,IF(C403="P134",353,IF(C403="P135",226,IF(C403="P136",604,IF(C403="P137",97,IF(C403="P138",465,IF(C403="P139",637,IF(C403="P140",307,0))))))))))))))))))) -> 183 | E403: 155 | F403: 9 | G403: =Sales_Table!$E403*F403 -> 1395 | H403: Debit | I403: =G403-(D403*F403) -> -252 | J403: =YEAR(Table16[[#This Row],[Date]]) -> 2022 | K403: =TEXT(Table16[[#This Row],[Date]],"MMMM") -> April
A404: 21/09/2020 | B404: O2403 | C404: P122 | D404: =IF(C404="P122",183,IF(C404="P123",371,IF(C404="P124",415,IF(C404="P125",508,IF(C404="P126",358,IF(C404="P127",712,IF(C404="P128",126,IF(C404="P129",280,IF(C404="P130",695,IF(C404="P131",216,IF(C404="P132",540,IF(C404="P133",181,IF(C404="P134",353,IF(C404="P135",226,IF(C404="P136",604,IF(C404="P137",97,IF(C404="P138",465,IF(C404="P139",637,IF(C404="P140",307,0))))))))))))))))))) -> 183 | E404: 155 | F404: 5 | G404: =Sales_Table!$E404*F404 -> 775 | H404: EMI | I404: =G404-(D404*F404) -> -140 | J404: =YEAR(Table16[[#This Row],[Date]]) -> 2020 | K404: =TEXT(Table16[[#This Row],[Date]],"MMMM") -> September
A405: 21/05/2021 | B405: O2404 | C405: P122 | D405: =IF(C405="P122",183,IF(C405="P123",371,IF(C405="P124",415,IF(C405="P125",508,IF(C405="P126",358,IF(C405="P127",712,IF(C405="P128",126,IF(C405="P129",280,IF(C405="P130",695,IF(C405="P131",216,IF(C405="P132",540,IF(C405="P133",181,IF(C405="P134",353,IF(C405="P135",226,IF(C405="P136",604,IF(C405="P137",97,IF(C405="P138",465,IF(C405="P139",637,IF(C405="P140",307,0))))))))))))))))))) -> 183 | E405: 155 | F405: 7 | G405: =Sales_Table!$E405*F405 -> 1085 | H405: Debit | I405: =G405-(D405*F405) -> -196 | J405: =YEAR(Table16[[#This Row],[Date]]) -> 2021 | K405: =TEXT(Table16[[#This Row],[Date]],"MMMM") -> May
A406: 06/09/2024 | B406: O2405 | C406: P122 | D406: =IF(C406="P122",183,IF(C406="P123",371,IF(C406="P124",415,IF(C406="P125",508,IF(C406="P126",358,IF(C406="P127",712,IF(C406="P128",126,IF(C406="P129",280,IF(C406="P130",695,IF(C406="P131",216,IF(C406="P132",540,IF(C406="P133",181,IF(C406="P134",353,IF(C406="P135",226,IF(C406="P136",604,IF(C406="P137",97,IF(C406="P138",465,IF(C406="P139",637,IF(C406="P140",307,0))))))))))))))))))) -> 183 | E406: 155 | F406: 2 | G406: =Sales_Table!$E406*F406 -> 310 | H406: COD | I406: =G406-(D406*F406) -> -56 | J406: =YEAR(Table16[[#This Row],[Date]]) -> 2024 | K406: =TEXT(Table16[[#This Row],[Date]],"MMMM") -> September
A407: 24/12/2020 | B407: O2406 | C407: P122 | D407: =IF(C407="P122",183,IF(C407="P123",371,IF(C407="P124",415,IF(C407="P125",508,IF(C407="P126",358,IF(C407="P127",712,IF(C407="P128",126,IF(C407="P129",280,IF(C407="P130",695,IF(C407="P131",216,IF(C407="P132",540,IF(C407="P133",181,IF(C407="P134",353,IF(C407="P135",226,IF(C407="P136",604,IF(C407="P137",97,IF(C407="P138",465,IF(C407="P139",637,IF(C407="P140",307,0))))))))))))))))))) -> 183 | E407: 155 | F407: 5 | G407: =Sales_Table!$E407*F407 -> 775 | H407: Credit | I407: =G407-(D407*F407) -> -140 | J407: =YEAR(Table16[[#This Row],[Date]]) -> 2020 | K407: =TEXT(Table16[[#This Row],[Date]],"MMMM") -> December
A408: 18/04/2020 | B408: O2407 | C408: P122 | D408: =IF(C408="P122",183,IF(C408="P123",371,IF(C408="P124",415,IF(C408="P125",508,IF(C408="P126",358,IF(C408="P127",712,IF(C408="P128",126,IF(C408="P129",280,IF(C408="P130",695,IF(C408="P131",216,IF(C408="P132",540,IF(C408="P133",181,IF(C408="P134",353,IF(C408="P135",226,IF(C408="P136",604,IF(C408="P137",97,IF(C408="P138",465,IF(C408="P139",637,IF(C408="P140",307,0))))))))))))))))))) -> 183 | E408: 155 | F408: 1 | G408: =Sales_Table!$E408*F408 -> 155 | H408: COD | I408: =G408-(D408*F408) -> -28 | J408: =YEAR(Table16[[#This Row],[Date]]) -> 2020 | K408: =TEXT(Table16[[#This Row],[Date]],"MMMM") -> April
A409: 13/03/2023 | B409: O2408 | C409: P122 | D409: =IF(C409="P122",183,IF(C409="P123",371,IF(C409="P124",415,IF(C409="P125",508,IF(C409="P126",358,IF(C409="P127",712,IF(C409="P128",126,IF(C409="P129",280,IF(C409="P130",695,IF(C409="P131",216,IF(C409="P132",540,IF(C409="P133",181,IF(C409="P134",353,IF(C409="P135",226,IF(C409="P136",604,IF(C409="P137",97,IF(C409="P138",465,IF(C409="P139",637,IF(C409="P140",307,0))))))))))))))))))) -> 183 | E409: 155 | F409: 6 | G409: =Sales_Table!$E409*F409 -> 930 | H409: Credit | I409: =G409-(D409*F409) -> -168 | J409: =YEAR(Table16[[#This Row],[Date]]) -> 2023 | K409: =TEXT(Table16[[#This Row],[Date]],"MMMM") -> March
A410: 15/06/2021 | B410: O2409 | C410: P122 | D410: =IF(C410="P122",183,IF(C410="P123",371,IF(C410="P124",415,IF(C410="P125",508,IF(C410="P126",358,IF(C410="P127",712,IF(C410="P128",126,IF(C410="P129",280,IF(C410="P130",695,IF(C410="P131",216,IF(C410="P132",540,IF(C410="P133",181,IF(C410="P134",353,IF(C410="P135",226,IF(C410="P136",604,IF(C410="P137",97,IF(C410="P138",465,IF(C410="P139",637,IF(C410="P140",307,0))))))))))))))))))) -> 183 | E410: 155 | F410: 2 | G410: =Sales_Table!$E410*F410 -> 310 | H410: EMI | I410: =G410-(D410*F410) -> -56 | J410: =YEAR(Table16[[#This Row],[Date]]) -> 2021 | K410: =TEXT(Table16[[#This Row],[Date]],"MMMM") -> June
A411: 13/12/2021 | B411: O2410 | C411: P122 | D411: =IF(C411="P122",183,IF(C411="P123",371,IF(C411="P124",415,IF(C411="P125",508,IF(C411="P126",358,IF(C411="P127",712,IF(C411="P128",126,IF(C411="P129",280,IF(C411="P130",695,IF(C411="P131",216,IF(C411="P132",540,IF(C411="P133",181,IF(C411="P134",353,IF(C411="P135",226,IF(C411="P136",604,IF(C411="P137",97,IF(C411="P138",465,IF(C411="P139",637,IF(C411="P140",307,0))))))))))))))))))) -> 183 | E411: 155 | F411: 6 | G411: =Sales_Table!$E411*F411 -> 930 | H411: Credit | I411: =G411-(D411*F411) -> -168 | J411: =YEAR(Table16[[#This Row],[Date]]) -> 2021 | K411: =TEXT(Table16[[#This Row],[Date]],"MMMM") -> December
A412: 15/09/2020 | B412: O2411 | C412: P122 | D412: =IF(C412="P122",183,IF(C412="P123",371,IF(C412="P124",415,IF(C412="P125",508,IF(C412="P126",358,IF(C412="P127",712,IF(C412="P128",126,IF(C412="P129",280,IF(C412="P130",695,IF(C412="P131",216,IF(C412="P132",540,IF(C412="P133",181,IF(C412="P134",353,IF(C412="P135",226,IF(C412="P136",604,IF(C412="P137",97,IF(C412="P138",465,IF(C412="P139",637,IF(C412="P140",307,0))))))))))))))))))) -> 183 | E412: 155 | F412: 5 | G412: =Sales_Table!$E412*F412 -> 775 | H412: COD | I412: =G412-(D412*F412) -> -140 | J412: =YEAR(Table16[[#This Row],[Date]]) -> 2020 | K412: =TEXT(Table16[[#This Row],[Date]],"MMMM") -> September
... A502: 21/03/2020 | B502: O2501 | C502: P126 | D502: =IF(C502="P122",183,IF(C502="P123",371,IF(C502="P124",415,IF(C502="P125",508,IF(C502="P126",358,IF(C502="P127",712,IF(C502="P128",126,IF(C502="P129",280,IF(C502="P130",695,IF(C502="P131",216,IF(C502="P132",540,IF(C502="P133",181,IF(C502="P134",353,IF(C502="P135",226,IF(C502="P136",604,IF(C502="P137",97,IF(C502="P138",465,IF(C502="P139",637,IF(C502="P140",307,0))))))))))))))))))) -> 358 | E502: 480 | F502: 4 | G502: =Sales_Table!$E502*F502 -> 1920 | H502: Credit | I502: =G502-(D502*F502) -> 488 | J502: =YEAR(Table16[[#This Row],[Date]]) -> 2020 | K502: =TEXT(Table16[[#This Row],[Date]],"MMMM") -> March
A503: 01/07/2022 | B503: O2502 | C503: P127 | D503: =IF(C503="P122",183,IF(C503="P123",371,IF(C503="P124",415,IF(C503="P125",508,IF(C503="P126",358,IF(C503="P127",712,IF(C503="P128",126,IF(C503="P129",280,IF(C503="P130",695,IF(C503="P131",216,IF(C503="P132",540,IF(C503="P133",181,IF(C503="P134",353,IF(C503="P135",226,IF(C503="P136",604,IF(C503="P137",97,IF(C503="P138",465,IF(C503="P139",637,IF(C503="P140",307,0))))))))))))))))))) -> 712 | E503: =IF(C503="P127",800,IF(C503="P128",180,IF(C503="P129",220,0))) -> 800 | F503: 9 | G503: =Sales_Table!$E503*F503 -> 7200 | H503: Debit | I503: =G503-(D503*F503) -> 792 | J503: =YEAR(Table16[[#This Row],[Date]]) -> 2022 | K503: =TEXT(Table16[[#This Row],[Date]],"MMMM") -> July
A504: 29/12/2024 | B504: O2503 | C504: P127 | D504: =IF(C504="P122",183,IF(C504="P123",371,IF(C504="P124",415,IF(C504="P125",508,IF(C504="P126",358,IF(C504="P127",712,IF(C504="P128",126,IF(C504="P129",280,IF(C504="P130",695,IF(C504="P131",216,IF(C504="P132",540,IF(C504="P133",181,IF(C504="P134",353,IF(C504="P135",226,IF(C504="P136",604,IF(C504="P137",97,IF(C504="P138",465,IF(C504="P139",637,IF(C504="P140",307,0))))))))))))))))))) -> 712 | E504: =IF(C504="P127",800,IF(C504="P128",180,IF(C504="P129",220,0))) -> 800 | F504: 2 | G504: =Sales_Table!$E504*F504 -> 1600 | H504: Credit | I504: =G504-(D504*F504) -> 176 | J504: =YEAR(Table16[[#This Row],[Date]]) -> 2024 | K504: =TEXT(Table16[[#This Row],[Date]],"MMMM") -> December
A505: 08/11/2024 | B505: O2504 | C505: P127 | D505: =IF(C505="P122",183,IF(C505="P123",371,IF(C505="P124",415,IF(C505="P125",508,IF(C505="P126",358,IF(C505="P127",712,IF(C505="P128",126,IF(C505="P129",280,IF(C505="P130",695,IF(C505="P131",216,IF(C505="P132",540,IF(C505="P133",181,IF(C505="P134",353,IF(C505="P135",226,IF(C505="P136",604,IF(C505="P137",97,IF(C505="P138",465,IF(C505="P139",637,IF(C505="P140",307,0))))))))))))))))))) -> 712 | E505: =IF(C505="P127",800,IF(C505="P128",180,IF(C505="P129",220,0))) -> 800 | F505: 10 | G505: =Sales_Table!$E505*F505 -> 8000 | H505: COD | I505: =G505-(D505*F505) -> 880 | J505: =YEAR(Table16[[#This Row],[Date]]) -> 2024 | K505: =TEXT(Table16[[#This Row],[Date]],"MMMM") -> November
A506: 13/08/2022 | B506: O2505 | C506: P127 | D506: =IF(C506="P122",183,IF(C506="P123",371,IF(C506="P124",415,IF(C506="P125",508,IF(C506="P126",358,IF(C506="P127",712,IF(C506="P128",126,IF(C506="P129",280,IF(C506="P130",695,IF(C506="P131",216,IF(C506="P132",540,IF(C506="P133",181,IF(C506="P134",353,IF(C506="P135",226,IF(C506="P136",604,IF(C506="P137",97,IF(C506="P138",465,IF(C506="P139",637,IF(C506="P140",307,0))))))))))))))))))) -> 712 | E506: =IF(C506="P127",800,IF(C506="P128",180,IF(C506="P129",220,0))) -> 800 | F506: 5 | G506: =Sales_Table!$E506*F506 -> 4000 | H506: Credit | I506: =G506-(D506*F506) -> 440 | J506: =YEAR(Table16[[#This Row],[Date]]) -> 2022 | K506: =TEXT(Table16[[#This Row],[Date]],"MMMM") -> August
A507: 11/03/2024 | B507: O2506 | C507: P127 | D507: =IF(C507="P122",183,IF(C507="P123",371,IF(C507="P124",415,IF(C507="P125",508,IF(C507="P126",358,IF(C507="P127",712,IF(C507="P128",126,IF(C507="P129",280,IF(C507="P130",695,IF(C507="P131",216,IF(C507="P132",540,IF(C507="P133",181,IF(C507="P134",353,IF(C507="P135",226,IF(C507="P136",604,IF(C507="P137",97,IF(C507="P138",465,IF(C507="P139",637,IF(C507="P140",307,0))))))))))))))))))) -> 712 | E507: =IF(C507="P127",800,IF(C507="P128",180,IF(C507="P129",220,0))) -> 800 | F507: 9 | G507: =Sales_Table!$E507*F507 -> 7200 | H507: COD | I507: =G507-(D507*F507) -> 792 | J507: =YEAR(Table16[[#This Row],[Date]]) -> 2024 | K507: =TEXT(Table16[[#This Row],[Date]],"MMMM") -> March
A508: 18/11/2020 | B508: O2507 | C508: P127 | D508: =IF(C508="P122",183,IF(C508="P123",371,IF(C508="P124",415,IF(C508="P125",508,IF(C508="P126",358,IF(C508="P127",712,IF(C508="P128",126,IF(C508="P129",280,IF(C508="P130",695,IF(C508="P131",216,IF(C508="P132",540,IF(C508="P133",181,IF(C508="P134",353,IF(C508="P135",226,IF(C508="P136",604,IF(C508="P137",97,IF(C508="P138",465,IF(C508="P139",637,IF(C508="P140",307,0))))))))))))))))))) -> 712 | E508: =IF(C508="P127",800,IF(C508="P128",180,IF(C508="P129",220,0))) -> 800 | F508: 6 | G508: =Sales_Table!$E508*F508 -> 4800 | H508: EMI | I508: =G508-(D508*F508) -> 528 | J508: =YEAR(Table16[[#This Row],[Date]]) -> 2020 | K508: =TEXT(Table16[[#This Row],[Date]],"MMMM") -> November
A509: 11/04/2020 | B509: O2508 | C509: P127 | D509: =IF(C509="P122",183,IF(C509="P123",371,IF(C509="P124",415,IF(C509="P125",508,IF(C509="P126",358,IF(C509="P127",712,IF(C509="P128",126,IF(C509="P129",280,IF(C509="P130",695,IF(C509="P131",216,IF(C509="P132",540,IF(C509="P133",181,IF(C509="P134",353,IF(C509="P135",226,IF(C509="P136",604,IF(C509="P137",97,IF(C509="P138",465,IF(C509="P139",637,IF(C509="P140",307,0))))))))))))))))))) -> 712 | E509: =IF(C509="P127",800,IF(C509="P128",180,IF(C509="P129",220,0))) -> 800 | F509: 2 | G509: =Sales_Table!$E509*F509 -> 1600 | H509: Debit | I509: =G509-(D509*F509) -> 176 | J509: =YEAR(Table16[[#This Row],[Date]]) -> 2020 | K509: =TEXT(Table16[[#This Row],[Date]],"MMMM") -> April
A510: 30/06/2021 | B510: O2509 | C510: P127 | D510: =IF(C510="P122",183,IF(C510="P123",371,IF(C510="P124",415,IF(C510="P125",508,IF(C510="P126",358,IF(C510="P127",712,IF(C510="P128",126,IF(C510="P129",280,IF(C510="P130",695,IF(C510="P131",216,IF(C510="P132",540,IF(C510="P133",181,IF(C510="P134",353,IF(C510="P135",226,IF(C510="P136",604,IF(C510="P137",97,IF(C510="P138",465,IF(C510="P139",637,IF(C510="P140",307,0))))))))))))))))))) -> 712 | E510: =IF(C510="P127",800,IF(C510="P128",180,IF(C510="P129",220,0))) -> 800 | F510: 7 | G510: =Sales_Table!$E510*F510 -> 5600 | H510: COD | I510: =G510-(D510*F510) -> 616 | J510: =YEAR(Table16[[#This Row],[Date]]) -> 2021 | K510: =TEXT(Table16[[#This Row],[Date]],"MMMM") -> June
A511: 06/06/2024 | B511: O2510 | C511: P127 | D511: =IF(C511="P122",183,IF(C511="P123",371,IF(C511="P124",415,IF(C511="P125",508,IF(C511="P126",358,IF(C511="P127",712,IF(C511="P128",126,IF(C511="P129",280,IF(C511="P130",695,IF(C511="P131",216,IF(C511="P132",540,IF(C511="P133",181,IF(C511="P134",353,IF(C511="P135",226,IF(C511="P136",604,IF(C511="P137",97,IF(C511="P138",465,IF(C511="P139",637,IF(C511="P140",307,0))))))))))))))))))) -> 712 | E511: =IF(C511="P127",800,IF(C511="P128",180,IF(C511="P129",220,0))) -> 800 | F511: 4 | G511: =Sales_Table!$E511*F511 -> 3200 | H511: Credit | I511: =G511-(D511*F511) -> 352 | J511: =YEAR(Table16[[#This Row],[Date]]) -> 2024 | K511: =TEXT(Table16[[#This Row],[Date]],"MMMM") -> June
A512: 01/02/2020 | B512: O2511 | C512: P127 | D512: =IF(C512="P122",183,IF(C512="P123",371,IF(C512="P124",415,IF(C512="P125",508,IF(C512="P126",358,IF(C512="P127",712,IF(C512="P128",126,IF(C512="P129",280,IF(C512="P130",695,IF(C512="P131",216,IF(C512="P132",540,IF(C512="P133",181,IF(C512="P134",353,IF(C512="P135",226,IF(C512="P136",604,IF(C512="P137",97,IF(C512="P138",465,IF(C512="P139",637,IF(C512="P140",307,0))))))))))))))))))) -> 712 | E512: =IF(C512="P127",800,IF(C512="P128",180,IF(C512="P129",220,0))) -> 800 | F512: 3 | G512: =Sales_Table!$E512*F512 -> 2400 | H512: COD | I512: =G512-(D512*F512) -> 264 | J512: =YEAR(Table16[[#This Row],[Date]]) -> 2020 | K512: =TEXT(Table16[[#This Row],[Date]],"MMMM") -> February
A513: 19/08/2021 | B513: O2512 | C513: P127 | D513: =IF(C513="P122",183,IF(C513="P123",371,IF(C513="P124",415,IF(C513="P125",508,IF(C513="P126",358,IF(C513="P127",712,IF(C513="P128",126,IF(C513="P129",280,IF(C513="P130",695,IF(C513="P131",216,IF(C513="P132",540,IF(C513="P133",181,IF(C513="P134",353,IF(C513="P135",226,IF(C513="P136",604,IF(C513="P137",97,IF(C513="P138",465,IF(C513="P139",637,IF(C513="P140",307,0))))))))))))))))))) -> 712 | E513: =IF(C513="P127",800,IF(C513="P128",180,IF(C513="P129",220,0))) -> 800 | F513: 3 | G513: =Sales_Table!$E513*F513 -> 2400 | H513: COD | I513: =G513-(D513*F513) -> 264 | J513: =YEAR(Table16[[#This Row],[Date]]) -> 2021 | K513: =TEXT(Table16[[#This Row],[Date]],"MMMM") -> August
A514: 28/03/2022 | B514: O2513 | C514: P127 | D514: =IF(C514="P122",183,IF(C514="P123",371,IF(C514="P124",415,IF(C514="P125",508,IF(C514="P126",358,IF(C514="P127",712,IF(C514="P128",126,IF(C514="P129",280,IF(C514="P130",695,IF(C514="P131",216,IF(C514="P132",540,IF(C514="P133",181,IF(C514="P134",353,IF(C514="P135",226,IF(C514="P136",604,IF(C514="P137",97,IF(C514="P138",465,IF(C514="P139",637,IF(C514="P140",307,0))))))))))))))))))) -> 712 | E514: =IF(C514="P127",800,IF(C514="P128",180,IF(C514="P129",220,0))) -> 800 | F514: 5 | G514: =Sales_Table!$E514*F514 -> 4000 | H514: COD | I514: =G514-(D514*F514) -> 440 | J514: =YEAR(Table16[[#This Row],[Date]]) -> 2022 | K514: =TEXT(Table16[[#This Row],[Date]],"MMMM") -> March
...

Sheet Inventory_Table
A1: Product_id | B1: Category | C1: Product_name | D1: Stock In | E1: Stock Out | F1: Current Stock
A2: P101 | B2: Toys & Games | C2: =IF(B2="Electronics", CHOOSE(RANDBETWEEN(1,5), "Smartphone", "Laptop", "Smartwatch", "Bluetooth Speaker", "Wireless Earbuds"), IF(B2="Clothing", CHOOSE(RANDBETWEEN(1,5), "T-shirt", "Jeans", "Jacket", "Hoodie", "Shorts"), IF(B2="Books", CHOOSE(RANDBETWEEN(1,5), "Novel", "Biography", "Comics", "Cookbook", "Textbook"), IF(B2="Footwear", CHOOSE(RANDBETWEEN(1,5), "Sneakers", "Sandals", "Boots", "Loafers", "Flip-flops"), IF(B2="Furniture", CHOOSE(RANDBETWEEN(1,5), "Chair", "Table", "Sofa", "Wardrobe", "Bed"), IF(B2="Home Appliances", CHOOSE(RANDBETWEEN(1,5), "Refrigerator", "Microwave", "Washing Machine", "Air Conditioner", "Vacuum Cleaner"), IF(B2="Beauty & Personal Care", CHOOSE(RANDBETWEEN(1,5), "Lipstick", "Moisturizer", "Perfume", "Shampoo", "Sunscreen"), IF(B2="Stationery", CHOOSE(RANDBETWEEN(1,5), "Pen", "Notebook", "Marker", "Stapler", "Eraser"), IF(B2="Toys & Games", CHOOSE(RANDBETWEEN(1,5), "Puzzle", "Action Figure", "Board Game", "Doll", "Remote Car"), IF(B2="Sports & Fitness", CHOOSE(RANDBETWEEN(1,5), "Treadmill", "Dumbbells", "Yoga Mat", "Bicycle", "Skipping Rope"), "Unknown")))))))))) -> Action Figure | D2: 190 | E2: =RANDBETWEEN(150, D2 - 1) -> 174 | F2: =D2-E2 -> 16
A3: P102 | B3: Footwear | C3: =IF(B3="Electronics", CHOOSE(RANDBETWEEN(1,5), "Smartphone", "Laptop", "Smartwatch", "Bluetooth Speaker", "Wireless Earbuds"), IF(B3="Clothing", CHOOSE(RANDBETWEEN(1,5), "T-shirt", "Jeans", "Jacket", "Hoodie", "Shorts"), IF(B3="Books", CHOOSE(RANDBETWEEN(1,5), "Novel", "Biography", "Comics", "Cookbook", "Textbook"), IF(B3="Footwear", CHOOSE(RANDBETWEEN(1,5), "Sneakers", "Sandals", "Boots", "Loafers", "Flip-flops"), IF(B3="Furniture", CHOOSE(RANDBETWEEN(1,5), "Chair", "Table", "Sofa", "Wardrobe", "Bed"), IF(B3="Home Appliances", CHOOSE(RANDBETWEEN(1,5), "Refrigerator", "Microwave", "Washing Machine", "Air Conditioner", "Vacuum Cleaner"), IF(B3="Beauty & Personal Care", CHOOSE(RANDBETWEEN(1,5), "Lipstick", "Moisturizer", "Perfume", "Shampoo", "Sunscreen"), IF(B3="Stationery", CHOOSE(RANDBETWEEN(1,5), "Pen", "Notebook", "Marker", "Stapler", "Eraser"), IF(B3="Toys & Games", CHOOSE(RANDBETWEEN(1,5), "Puzzle", "Action Figure", "Board Game", "Doll", "Remote Car"), IF(B3="Sports & Fitness", CHOOSE(RANDBETWEEN(1,5), "Treadmill", "Dumbbells", "Yoga Mat", "Bicycle", "Skipping Rope"), "Unknown")))))))))) -> Loafers | D3: 411 | E3: =RANDBETWEEN(150, D3 - 1) -> 216 | F3: =D3-E3 -> 195
A4: P103 | B4: Electronics | C4: =IF(B4="Electronics", CHOOSE(RANDBETWEEN(1,5), "Smartphone", "Laptop", "Smartwatch", "Bluetooth Speaker", "Wireless Earbuds"), IF(B4="Clothing", CHOOSE(RANDBETWEEN(1,5), "T-shirt", "Jeans", "Jacket", "Hoodie", "Shorts"), IF(B4="Books", CHOOSE(RANDBETWEEN(1,5), "Novel", "Biography", "Comics", "Cookbook", "Textbook"), IF(B4="Footwear", CHOOSE(RANDBETWEEN(1,5), "Sneakers", "Sandals", "Boots", "Loafers", "Flip-flops"), IF(B4="Furniture", CHOOSE(RANDBETWEEN(1,5), "Chair", "Table", "Sofa", "Wardrobe", "Bed"), IF(B4="Home Appliances", CHOOSE(RANDBETWEEN(1,5), "Refrigerator", "Microwave", "Washing Machine", "Air Conditioner", "Vacuum Cleaner"), IF(B4="Beauty & Personal Care", CHOOSE(RANDBETWEEN(1,5), "Lipstick", "Moisturizer", "Perfume", "Shampoo", "Sunscreen"), IF(B4="Stationery", CHOOSE(RANDBETWEEN(1,5), "Pen", "Notebook", "Marker", "Stapler", "Eraser"), IF(B4="Toys & Games", CHOOSE(RANDBETWEEN(1,5), "Puzzle", "Action Figure", "Board Game", "Doll", "Remote Car"), IF(B4="Sports & Fitness", CHOOSE(RANDBETWEEN(1,5), "Treadmill", "Dumbbells", "Yoga Mat", "Bicycle", "Skipping Rope"), "Unknown")))))))))) -> Wireless Earbuds | D4: 446 | E4: =RANDBETWEEN(150, D4 - 1) -> 373 | F4: =D4-E4 -> 73
A5: P104 | B5: Sports & Fitness | C5: =IF(B5="Electronics", CHOOSE(RANDBETWEEN(1,5), "Smartphone", "Laptop", "Smartwatch", "Bluetooth Speaker", "Wireless Earbuds"), IF(B5="Clothing", CHOOSE(RANDBETWEEN(1,5), "T-shirt", "Jeans", "Jacket", "Hoodie", "Shorts"), IF(B5="Books", CHOOSE(RANDBETWEEN(1,5), "Novel", "Biography", "Comics", "Cookbook", "Textbook"), IF(B5="Footwear", CHOOSE(RANDBETWEEN(1,5), "Sneakers", "Sandals", "Boots", "Loafers", "Flip-flops"), IF(B5="Furniture", CHOOSE(RANDBETWEEN(1,5), "Chair", "Table", "Sofa", "Wardrobe", "Bed"), IF(B5="Home Appliances", CHOOSE(RANDBETWEEN(1,5), "Refrigerator", "Microwave", "Washing Machine", "Air Conditioner", "Vacuum Cleaner"), IF(B5="Beauty & Personal Care", CHOOSE(RANDBETWEEN(1,5), "Lipstick", "Moisturizer", "Perfume", "Shampoo", "Sunscreen"), IF(B5="Stationery", CHOOSE(RANDBETWEEN(1,5), "Pen", "Notebook", "Marker", "Stapler", "Eraser"), IF(B5="Toys & Games", CHOOSE(RANDBETWEEN(1,5), "Puzzle", "Action Figure", "Board Game", "Doll", "Remote Car"), IF(B5="Sports & Fitness", CHOOSE(RANDBETWEEN(1,5), "Treadmill", "Dumbbells", "Yoga Mat", "Bicycle", "Skipping Rope"), "Unknown")))))))))) -> Treadmill | D5: 322 | E5: =RANDBETWEEN(150, D5 - 1) -> 316 | F5: =D5-E5 -> 6
A6: P105 | B6: Footwear | C6: =IF(B6="Electronics", CHOOSE(RANDBETWEEN(1,5), "Smartphone", "Laptop", "Smartwatch", "Bluetooth Speaker", "Wireless Earbuds"), IF(B6="Clothing", CHOOSE(RANDBETWEEN(1,5), "T-shirt", "Jeans", "Jacket", "Hoodie", "Shorts"), IF(B6="Books", CHOOSE(RANDBETWEEN(1,5), "Novel", "Biography", "Comics", "Cookbook", "Textbook"), IF(B6="Footwear", CHOOSE(RANDBETWEEN(1,5), "Sneakers", "Sandals", "Boots", "Loafers", "Flip-flops"), IF(B6="Furniture", CHOOSE(RANDBETWEEN(1,5), "Chair", "Table", "Sofa", "Wardrobe", "Bed"), IF(B6="Home Appliances", CHOOSE(RANDBETWEEN(1,5), "Refrigerator", "Microwave", "Washing Machine", "Air Conditioner", "Vacuum Cleaner"), IF(B6="Beauty & Personal Care", CHOOSE(RANDBETWEEN(1,5), "Lipstick", "Moisturizer", "Perfume", "Shampoo", "Sunscreen"), IF(B6="Stationery", CHOOSE(RANDBETWEEN(1,5), "Pen", "Notebook", "Marker", "Stapler", "Eraser"), IF(B6="Toys & Games", CHOOSE(RANDBETWEEN(1,5), "Puzzle", "Action Figure", "Board Game", "Doll", "Remote Car"), IF(B6="Sports & Fitness", CHOOSE(RANDBETWEEN(1,5), "Treadmill", "Dumbbells", "Yoga Mat", "Bicycle", "Skipping Rope"), "Unknown")))))))))) -> Sandals | D6: 269 | E6: =RANDBETWEEN(150, D6 - 1) -> 222 | F6: =D6-E6 -> 47
A7: P106 | B7: Stationery | C7: =IF(B7="Electronics", CHOOSE(RANDBETWEEN(1,5), "Smartphone", "Laptop", "Smartwatch", "Bluetooth Speaker", "Wireless Earbuds"), IF(B7="Clothing", CHOOSE(RANDBETWEEN(1,5), "T-shirt", "Jeans", "Jacket", "Hoodie", "Shorts"), IF(B7="Books", CHOOSE(RANDBETWEEN(1,5), "Novel", "Biography", "Comics", "Cookbook", "Textbook"), IF(B7="Footwear", CHOOSE(RANDBETWEEN(1,5), "Sneakers", "Sandals", "Boots", "Loafers", "Flip-flops"), IF(B7="Furniture", CHOOSE(RANDBETWEEN(1,5), "Chair", "Table", "Sofa", "Wardrobe", "Bed"), IF(B7="Home Appliances", CHOOSE(RANDBETWEEN(1,5), "Refrigerator", "Microwave", "Washing Machine", "Air Conditioner", "Vacuum Cleaner"), IF(B7="Beauty & Personal Care", CHOOSE(RANDBETWEEN(1,5), "Lipstick", "Moisturizer", "Perfume", "Shampoo", "Sunscreen"), IF(B7="Stationery", CHOOSE(RANDBETWEEN(1,5), "Pen", "Notebook", "Marker", "Stapler", "Eraser"), IF(B7="Toys & Games", CHOOSE(RANDBETWEEN(1,5), "Puzzle", "Action Figure", "Board Game", "Doll", "Remote Car"), IF(B7="Sports & Fitness", CHOOSE(RANDBETWEEN(1,5), "Treadmill", "Dumbbells", "Yoga Mat", "Bicycle", "Skipping Rope"), "Unknown")))))))))) -> Marker | D7: 432 | E7: =RANDBETWEEN(150, D7 - 1) -> 175 | F7: =D7-E7 -> 257
A8: P107 | B8: Beauty & Personal Care | C8: =IF(B8="Electronics", CHOOSE(RANDBETWEEN(1,5), "Smartphone", "Laptop", "Smartwatch", "Bluetooth Speaker", "Wireless Earbuds"), IF(B8="Clothing", CHOOSE(RANDBETWEEN(1,5), "T-shirt", "Jeans", "Jacket", "Hoodie", "Shorts"), IF(B8="Books", CHOOSE(RANDBETWEEN(1,5), "Novel", "Biography", "Comics", "Cookbook", "Textbook"), IF(B8="Footwear", CHOOSE(RANDBETWEEN(1,5), "Sneakers", "Sandals", "Boots", "Loafers", "Flip-flops"), IF(B8="Furniture", CHOOSE(RANDBETWEEN(1,5), "Chair", "Table", "Sofa", "Wardrobe", "Bed"), IF(B8="Home Appliances", CHOOSE(RANDBETWEEN(1,5), "Refrigerator", "Microwave", "Washing Machine", "Air Conditioner", "Vacuum Cleaner"), IF(B8="Beauty & Personal Care", CHOOSE(RANDBETWEEN(1,5), "Lipstick", "Moisturizer", "Perfume", "Shampoo", "Sunscreen"), IF(B8="Stationery", CHOOSE(RANDBETWEEN(1,5), "Pen", "Notebook", "Marker", "Stapler", "Eraser"), IF(B8="Toys & Games", CHOOSE(RANDBETWEEN(1,5), "Puzzle", "Action Figure", "Board Game", "Doll", "Remote Car"), IF(B8="Sports & Fitness", CHOOSE(RANDBETWEEN(1,5), "Treadmill", "Dumbbells", "Yoga Mat", "Bicycle", "Skipping Rope"), "Unknown")))))))))) -> Shampoo | D8: 232 | E8: =RANDBETWEEN(150, D8 - 1) -> 162 | F8: =D8-E8 -> 70
A9: P108 | B9: Sports & Fitness | C9: =IF(B9="Electronics", CHOOSE(RANDBETWEEN(1,5), "Smartphone", "Laptop", "Smartwatch", "Bluetooth Speaker", "Wireless Earbuds"), IF(B9="Clothing", CHOOSE(RANDBETWEEN(1,5), "T-shirt", "Jeans", "Jacket", "Hoodie", "Shorts"), IF(B9="Books", CHOOSE(RANDBETWEEN(1,5), "Novel", "Biography", "Comics", "Cookbook", "Textbook"), IF(B9="Footwear", CHOOSE(RANDBETWEEN(1,5), "Sneakers", "Sandals", "Boots", "Loafers", "Flip-flops"), IF(B9="Furniture", CHOOSE(RANDBETWEEN(1,5), "Chair", "Table", "Sofa", "Wardrobe", "Bed"), IF(B9="Home Appliances", CHOOSE(RANDBETWEEN(1,5), "Refrigerator", "Microwave", "Washing Machine", "Air Conditioner", "Vacuum Cleaner"), IF(B9="Beauty & Personal Care", CHOOSE(RANDBETWEEN(1,5), "Lipstick", "Moisturizer", "Perfume", "Shampoo", "Sunscreen"), IF(B9="Stationery", CHOOSE(RANDBETWEEN(1,5), "Pen", "Notebook", "Marker", "Stapler", "Eraser"), IF(B9="Toys & Games", CHOOSE(RANDBETWEEN(1,5), "Puzzle", "Action Figure", "Board Game", "Doll", "Remote Car"), IF(B9="Sports & Fitness", CHOOSE(RANDBETWEEN(1,5), "Treadmill", "Dumbbells", "Yoga Mat", "Bicycle", "Skipping Rope"), "Unknown")))))))))) -> Skipping Rope | D9: 311 | E9: =RANDBETWEEN(150, D9 - 1) -> 172 | F9: =D9-E9 -> 139
A10: P109 | B10: Toys & Games | C10: =IF(B10="Electronics", CHOOSE(RANDBETWEEN(1,5), "Smartphone", "Laptop", "Smartwatch", "Bluetooth Speaker", "Wireless Earbuds"), IF(B10="Clothing", CHOOSE(RANDBETWEEN(1,5), "T-shirt", "Jeans", "Jacket", "Hoodie", "Shorts"), IF(B10="Books", CHOOSE(RANDBETWEEN(1,5), "Novel", "Biography", "Comics", "Cookbook", "Textbook"), IF(B10="Footwear", CHOOSE(RANDBETWEEN(1,5), "Sneakers", "Sandals", "Boots", "Loafers", "Flip-flops"), IF(B10="Furniture", CHOOSE(RANDBETWEEN(1,5), "Chair", "Table", "Sofa", "Wardrobe", "Bed"), IF(B10="Home Appliances", CHOOSE(RANDBETWEEN(1,5), "Refrigerator", "Microwave", "Washing Machine", "Air Conditioner", "Vacuum Cleaner"), IF(B10="Beauty & Personal Care", CHOOSE(RANDBETWEEN(1,5), "Lipstick", "Moisturizer", "Perfume", "Shampoo", "Sunscreen"), IF(B10="Stationery", CHOOSE(RANDBETWEEN(1,5), "Pen", "Notebook", "Marker", "Stapler", "Eraser"), IF(B10="Toys & Games", CHOOSE(RANDBETWEEN(1,5), "Puzzle", "Action Figure", "Board Game", "Doll", "Remote Car"), IF(B10="Sports & Fitness", CHOOSE(RANDBETWEEN(1,5), "Treadmill", "Dumbbells", "Yoga Mat", "Bicycle", "Skipping Rope"), "Unknown")))))))))) -> Action Figure | D10: 324 | E10: =RANDBETWEEN(150, D10 - 1) -> 294 | F10: =D10-E10 -> 30
A11: P110 | B11: Home Appliances | C11: =IF(B11="Electronics", CHOOSE(RANDBETWEEN(1,5), "Smartphone", "Laptop", "Smartwatch", "Bluetooth Speaker", "Wireless Earbuds"), IF(B11="Clothing", CHOOSE(RANDBETWEEN(1,5), "T-shirt", "Jeans", "Jacket", "Hoodie", "Shorts"), IF(B11="Books", CHOOSE(RANDBETWEEN(1,5), "Novel", "Biography", "Comics", "Cookbook", "Textbook"), IF(B11="Footwear", CHOOSE(RANDBETWEEN(1,5), "Sneakers", "Sandals", "Boots", "Loafers", "Flip-flops"), IF(B11="Furniture", CHOOSE(RANDBETWEEN(1,5), "Chair", "Table", "Sofa", "Wardrobe", "Bed"), IF(B11="Home Appliances", CHOOSE(RANDBETWEEN(1,5), "Refrigerator", "Microwave", "Washing Machine", "Air Conditioner", "Vacuum Cleaner"), IF(B11="Beauty & Personal Care", CHOOSE(RANDBETWEEN(1,5), "Lipstick", "Moisturizer", "Perfume", "Shampoo", "Sunscreen"), IF(B11="Stationery", CHOOSE(RANDBETWEEN(1,5), "Pen", "Notebook", "Marker", "Stapler", "Eraser"), IF(B11="Toys & Games", CHOOSE(RANDBETWEEN(1,5), "Puzzle", "Action Figure", "Board Game", "Doll", "Remote Car"), IF(B11="Sports & Fitness", CHOOSE(RANDBETWEEN(1,5), "Treadmill", "Dumbbells", "Yoga Mat", "Bicycle", "Skipping Rope"), "Unknown")))))))))) -> Air Conditioner | D11: 448 | E11: =RANDBETWEEN(150, D11 - 1) -> 298 | F11: =D11-E11 -> 150
A12: P111 | B12: Home Appliances | C12: =IF(B12="Electronics", CHOOSE(RANDBETWEEN(1,5), "Smartphone", "Laptop", "Smartwatch", "Bluetooth Speaker", "Wireless Earbuds"), IF(B12="Clothing", CHOOSE(RANDBETWEEN(1,5), "T-shirt", "Jeans", "Jacket", "Hoodie", "Shorts"), IF(B12="Books", CHOOSE(RANDBETWEEN(1,5), "Novel", "Biography", "Comics", "Cookbook", "Textbook"), IF(B12="Footwear", CHOOSE(RANDBETWEEN(1,5), "Sneakers", "Sandals", "Boots", "Loafers", "Flip-flops"), IF(B12="Furniture", CHOOSE(RANDBETWEEN(1,5), "Chair", "Table", "Sofa", "Wardrobe", "Bed"), IF(B12="Home Appliances", CHOOSE(RANDBETWEEN(1,5), "Refrigerator", "Microwave", "Washing Machine", "Air Conditioner", "Vacuum Cleaner"), IF(B12="Beauty & Personal Care", CHOOSE(RANDBETWEEN(1,5), "Lipstick", "Moisturizer", "Perfume", "Shampoo", "Sunscreen"), IF(B12="Stationery", CHOOSE(RANDBETWEEN(1,5), "Pen", "Notebook", "Marker", "Stapler", "Eraser"), IF(B12="Toys & Games", CHOOSE(RANDBETWEEN(1,5), "Puzzle", "Action Figure", "Board Game", "Doll", "Remote Car"), IF(B12="Sports & Fitness", CHOOSE(RANDBETWEEN(1,5), "Treadmill", "Dumbbells", "Yoga Mat", "Bicycle", "Skipping Rope"), "Unknown")))))))))) -> Microwave | D12: 301 | E12: =RANDBETWEEN(150, D12 - 1) -> 255 | F12: =D12-E12 -> 46
A13: P112 | B13: Clothing | C13: =IF(B13="Electronics", CHOOSE(RANDBETWEEN(1,5), "Smartphone", "Laptop", "Smartwatch", "Bluetooth Speaker", "Wireless Earbuds"), IF(B13="Clothing", CHOOSE(RANDBETWEEN(1,5), "T-shirt", "Jeans", "Jacket", "Hoodie", "Shorts"), IF(B13="Books", CHOOSE(RANDBETWEEN(1,5), "Novel", "Biography", "Comics", "Cookbook", "Textbook"), IF(B13="Footwear", CHOOSE(RANDBETWEEN(1,5), "Sneakers", "Sandals", "Boots", "Loafers", "Flip-flops"), IF(B13="Furniture", CHOOSE(RANDBETWEEN(1,5), "Chair", "Table", "Sofa", "Wardrobe", "Bed"), IF(B13="Home Appliances", CHOOSE(RANDBETWEEN(1,5), "Refrigerator", "Microwave", "Washing Machine", "Air Conditioner", "Vacuum Cleaner"), IF(B13="Beauty & Personal Care", CHOOSE(RANDBETWEEN(1,5), "Lipstick", "Moisturizer", "Perfume", "Shampoo", "Sunscreen"), IF(B13="Stationery", CHOOSE(RANDBETWEEN(1,5), "Pen", "Notebook", "Marker", "Stapler", "Eraser"), IF(B13="Toys & Games", CHOOSE(RANDBETWEEN(1,5), "Puzzle", "Action Figure", "Board Game", "Doll", "Remote Car"), IF(B13="Sports & Fitness", CHOOSE(RANDBETWEEN(1,5), "Treadmill", "Dumbbells", "Yoga Mat", "Bicycle", "Skipping Rope"), "Unknown")))))))))) -> Jeans | D13: 302 | E13: =RANDBETWEEN(150, D13 - 1) -> 251 | F13: =D13-E13 -> 51
... A51: P150 | B51: Toys & Games | C51: =IF(B51="Electronics", CHOOSE(RANDBETWEEN(1,5), "Smartphone", "Laptop", "Smartwatch", "Bluetooth Speaker", "Wireless Earbuds"), IF(B51="Clothing", CHOOSE(RANDBETWEEN(1,5), "T-shirt", "Jeans", "Jacket", "Hoodie", "Shorts"), IF(B51="Books", CHOOSE(RANDBETWEEN(1,5), "Novel", "Biography", "Comics", "Cookbook", "Textbook"), IF(B51="Footwear", CHOOSE(RANDBETWEEN(1,5), "Sneakers", "Sandals", "Boots", "Loafers", "Flip-flops"), IF(B51="Furniture", CHOOSE(RANDBETWEEN(1,5), "Chair", "Table", "Sofa", "Wardrobe", "Bed"), IF(B51="Home Appliances", CHOOSE(RANDBETWEEN(1,5), "Refrigerator", "Microwave", "Washing Machine", "Air Conditioner", "Vacuum Cleaner"), IF(B51="Beauty & Personal Care", CHOOSE(RANDBETWEEN(1,5), "Lipstick", "Moisturizer", "Perfume", "Shampoo", "Sunscreen"), IF(B51="Stationery", CHOOSE(RANDBETWEEN(1,5), "Pen", "Notebook", "Marker", "Stapler", "Eraser"), IF(B51="Toys & Games", CHOOSE(RANDBETWEEN(1,5), "Puzzle", "Action Figure", "Board Game", "Doll", "Remote Car"), IF(B51="Sports & Fitness", CHOOSE(RANDBETWEEN(1,5), "Treadmill", "Dumbbells", "Yoga Mat", "Bicycle", "Skipping Rope"), "Unknown")))))))))) -> Action Figure | D51: 289 | E51: =RANDBETWEEN(150, D51 - 1) -> 179 | F51: =D51-E51 -> 110

Sheet Product_Table
A1: Product_id | B1: Category | C1: Product_name | D1: Cost | E1: Supplier
A2: P101 | B2: Toys & Games | C2: =IF(B2="Electronics", CHOOSE(RANDBETWEEN(1,5), "Smartphone", "Laptop", "Smartwatch", "Bluetooth Speaker", "Wireless Earbuds"), IF(B2="Clothing", CHOOSE(RANDBETWEEN(1,5), "T-shirt", "Jeans", "Jacket", "Hoodie", "Shorts"), IF(B2="Books", CHOOSE(RANDBETWEEN(1,5), "Novel", "Biography", "Comics", "Cookbook", "Textbook"), IF(B2="Footwear", CHOOSE(RANDBETWEEN(1,5), "Sneakers", "Sandals", "Boots", "Loafers", "Flip-flops"), IF(B2="Furniture", CHOOSE(RANDBETWEEN(1,5), "Chair", "Table", "Sofa", "Wardrobe", "Bed"), IF(B2="Home Appliances", CHOOSE(RANDBETWEEN(1,5), "Refrigerator", "Microwave", "Washing Machine", "Air Conditioner", "Vacuum Cleaner"), IF(B2="Beauty & Personal Care", CHOOSE(RANDBETWEEN(1,5), "Lipstick", "Moisturizer", "Perfume", "Shampoo", "Sunscreen"), IF(B2="Stationery", CHOOSE(RANDBETWEEN(1,5), "Pen", "Notebook", "Marker", "Stapler", "Eraser"), IF(B2="Toys & Games", CHOOSE(RANDBETWEEN(1,5), "Puzzle", "Action Figure", "Board Game", "Doll", "Remote Car"), IF(B2="Sports & Fitness", CHOOSE(RANDBETWEEN(1,5), "Treadmill", "Dumbbells", "Yoga Mat", "Bicycle", "Skipping Rope"), "Unknown")))))))))) -> Action Figure | D2: 271 | E2: ShopPro Distributors
A3: P102 | B3: Footwear | C3: =IF(B3="Electronics", CHOOSE(RANDBETWEEN(1,5), "Smartphone", "Laptop", "Smartwatch", "Bluetooth Speaker", "Wireless Earbuds"), IF(B3="Clothing", CHOOSE(RANDBETWEEN(1,5), "T-shirt", "Jeans", "Jacket", "Hoodie", "Shorts"), IF(B3="Books", CHOOSE(RANDBETWEEN(1,5), "Novel", "Biography", "Comics", "Cookbook", "Textbook"), IF(B3="Footwear", CHOOSE(RANDBETWEEN(1,5), "Sneakers", "Sandals", "Boots", "Loafers", "Flip-flops"), IF(B3="Furniture", CHOOSE(RANDBETWEEN(1,5), "Chair", "Table", "Sofa", "Wardrobe", "Bed"), IF(B3="Home Appliances", CHOOSE(RANDBETWEEN(1,5), "Refrigerator", "Microwave", "Washing Machine", "Air Conditioner", "Vacuum Cleaner"), IF(B3="Beauty & Personal Care", CHOOSE(RANDBETWEEN(1,5), "Lipstick", "Moisturizer", "Perfume", "Shampoo", "Sunscreen"), IF(B3="Stationery", CHOOSE(RANDBETWEEN(1,5), "Pen", "Notebook", "Marker", "Stapler", "Eraser"), IF(B3="Toys & Games", CHOOSE(RANDBETWEEN(1,5), "Puzzle", "Action Figure", "Board Game", "Doll", "Remote Car"), IF(B3="Sports & Fitness", CHOOSE(RANDBETWEEN(1,5), "Treadmill", "Dumbbells", "Yoga Mat", "Bicycle", "Skipping Rope"), "Unknown")))))))))) -> Loafers | D3: 408 | E3: SwiftMart Distributors
A4: P103 | B4: Electronics | C4: =IF(B4="Electronics", CHOOSE(RANDBETWEEN(1,5), "Smartphone", "Laptop", "Smartwatch", "Bluetooth Speaker", "Wireless Earbuds"), IF(B4="Clothing", CHOOSE(RANDBETWEEN(1,5), "T-shirt", "Jeans", "Jacket", "Hoodie", "Shorts"), IF(B4="Books", CHOOSE(RANDBETWEEN(1,5), "Novel", "Biography", "Comics", "Cookbook", "Textbook"), IF(B4="Footwear", CHOOSE(RANDBETWEEN(1,5), "Sneakers", "Sandals", "Boots", "Loafers", "Flip-flops"), IF(B4="Furniture", CHOOSE(RANDBETWEEN(1,5), "Chair", "Table", "Sofa", "Wardrobe", "Bed"), IF(B4="Home Appliances", CHOOSE(RANDBETWEEN(1,5), "Refrigerator", "Microwave", "Washing Machine", "Air Conditioner", "Vacuum Cleaner"), IF(B4="Beauty & Personal Care", CHOOSE(RANDBETWEEN(1,5), "Lipstick", "Moisturizer", "Perfume", "Shampoo", "Sunscreen"), IF(B4="Stationery", CHOOSE(RANDBETWEEN(1,5), "Pen", "Notebook", "Marker", "Stapler", "Eraser"), IF(B4="Toys & Games", CHOOSE(RANDBETWEEN(1,5), "Puzzle", "Action Figure", "Board Game", "Doll", "Remote Car"), IF(B4="Sports & Fitness", CHOOSE(RANDBETWEEN(1,5), "Treadmill", "Dumbbells", "Yoga Mat", "Bicycle", "Skipping Rope"), "Unknown")))))))))) -> Wireless Earbuds | D4: 735 | E4: Bazaar World Importers
A5: P104 | B5: Sports & Fitness | C5: =IF(B5="Electronics", CHOOSE(RANDBETWEEN(1,5), "Smartphone", "Laptop", "Smartwatch", "Bluetooth Speaker", "Wireless Earbuds"), IF(B5="Clothing", CHOOSE(RANDBETWEEN(1,5), "T-shirt", "Jeans", "Jacket", "Hoodie", "Shorts"), IF(B5="Books", CHOOSE(RANDBETWEEN(1,5), "Novel", "Biography", "Comics", "Cookbook", "Textbook"), IF(B5="Footwear", CHOOSE(RANDBETWEEN(1,5), "Sneakers", "Sandals", "Boots", "Loafers", "Flip-flops"), IF(B5="Furniture", CHOOSE(RANDBETWEEN(1,5), "Chair", "Table", "Sofa", "Wardrobe", "Bed"), IF(B5="Home Appliances", CHOOSE(RANDBETWEEN(1,5), "Refrigerator", "Microwave", "Washing Machine", "Air Conditioner", "Vacuum Cleaner"), IF(B5="Beauty & Personal Care", CHOOSE(RANDBETWEEN(1,5), "Lipstick", "Moisturizer", "Perfume", "Shampoo", "Sunscreen"), IF(B5="Stationery", CHOOSE(RANDBETWEEN(1,5), "Pen", "Notebook", "Marker", "Stapler", "Eraser"), IF(B5="Toys & Games", CHOOSE(RANDBETWEEN(1,5), "Puzzle", "Action Figure", "Board Game", "Doll", "Remote Car"), IF(B5="Sports & Fitness", CHOOSE(RANDBETWEEN(1,5), "Treadmill", "Dumbbells", "Yoga Mat", "Bicycle", "Skipping Rope"), "Unknown")))))))))) -> Dumbbells | D5: 749 | E5: ProGear Supply Co.
A6: P105 | B6: Footwear | C6: =IF(B6="Electronics", CHOOSE(RANDBETWEEN(1,5), "Smartphone", "Laptop", "Smartwatch", "Bluetooth Speaker", "Wireless Earbuds"), IF(B6="Clothing", CHOOSE(RANDBETWEEN(1,5), "T-shirt", "Jeans", "Jacket", "Hoodie", "Shorts"), IF(B6="Books", CHOOSE(RANDBETWEEN(1,5), "Novel", "Biography", "Comics", "Cookbook", "Textbook"), IF(B6="Footwear", CHOOSE(RANDBETWEEN(1,5), "Sneakers", "Sandals", "Boots", "Loafers", "Flip-flops"), IF(B6="Furniture", CHOOSE(RANDBETWEEN(1,5), "Chair", "Table", "Sofa", "Wardrobe", "Bed"), IF(B6="Home Appliances", CHOOSE(RANDBETWEEN(1,5), "Refrigerator", "Microwave", "Washing Machine", "Air Conditioner", "Vacuum Cleaner"), IF(B6="Beauty & Personal Care", CHOOSE(RANDBETWEEN(1,5), "Lipstick", "Moisturizer", "Perfume", "Shampoo", "Sunscreen"), IF(B6="Stationery", CHOOSE(RANDBETWEEN(1,5), "Pen", "Notebook", "Marker", "Stapler", "Eraser"), IF(B6="Toys & Games", CHOOSE(RANDBETWEEN(1,5), "Puzzle", "Action Figure", "Board Game", "Doll", "Remote Car"), IF(B6="Sports & Fitness", CHOOSE(RANDBETWEEN(1,5), "Treadmill", "Dumbbells", "Yoga Mat", "Bicycle", "Skipping Rope"), "Unknown")))))))))) -> Sneakers | D6: 807 | E6: Velocity Retailers
A7: P106 | B7: Stationery | C7: =IF(B7="Electronics", CHOOSE(RANDBETWEEN(1,5), "Smartphone", "Laptop", "Smartwatch", "Bluetooth Speaker", "Wireless Earbuds"), IF(B7="Clothing", CHOOSE(RANDBETWEEN(1,5), "T-shirt", "Jeans", "Jacket", "Hoodie", "Shorts"), IF(B7="Books", CHOOSE(RANDBETWEEN(1,5), "Novel", "Biography", "Comics", "Cookbook", "Textbook"), IF(B7="Footwear", CHOOSE(RANDBETWEEN(1,5), "Sneakers", "Sandals", "Boots", "Loafers", "Flip-flops"), IF(B7="Furniture", CHOOSE(RANDBETWEEN(1,5), "Chair", "Table", "Sofa", "Wardrobe", "Bed"), IF(B7="Home Appliances", CHOOSE(RANDBETWEEN(1,5), "Refrigerator", "Microwave", "Washing Machine", "Air Conditioner", "Vacuum Cleaner"), IF(B7="Beauty & Personal Care", CHOOSE(RANDBETWEEN(1,5), "Lipstick", "Moisturizer", "Perfume", "Shampoo", "Sunscreen"), IF(B7="Stationery", CHOOSE(RANDBETWEEN(1,5), "Pen", "Notebook", "Marker", "Stapler", "Eraser"), IF(B7="Toys & Games", CHOOSE(RANDBETWEEN(1,5), "Puzzle", "Action Figure", "Board Game", "Doll", "Remote Car"), IF(B7="Sports & Fitness", CHOOSE(RANDBETWEEN(1,5), "Treadmill", "Dumbbells", "Yoga Mat", "Bicycle", "Skipping Rope"), "Unknown")))))))))) -> Stapler | D7: 365 | E7: Trendy Hub Ltd.
A8: P107 | B8: Beauty & Personal Care | C8: =IF(B8="Electronics", CHOOSE(RANDBETWEEN(1,5), "Smartphone", "Laptop", "Smartwatch", "Bluetooth Speaker", "Wireless Earbuds"), IF(B8="Clothing", CHOOSE(RANDBETWEEN(1,5), "T-shirt", "Jeans", "Jacket", "Hoodie", "Shorts"), IF(B8="Books", CHOOSE(RANDBETWEEN(1,5), "Novel", "Biography", "Comics", "Cookbook", "Textbook"), IF(B8="Footwear", CHOOSE(RANDBETWEEN(1,5), "Sneakers", "Sandals", "Boots", "Loafers", "Flip-flops"), IF(B8="Furniture", CHOOSE(RANDBETWEEN(1,5), "Chair", "Table", "Sofa", "Wardrobe", "Bed"), IF(B8="Home Appliances", CHOOSE(RANDBETWEEN(1,5), "Refrigerator", "Microwave", "Washing Machine", "Air Conditioner", "Vacuum Cleaner"), IF(B8="Beauty & Personal Care", CHOOSE(RANDBETWEEN(1,5), "Lipstick", "Moisturizer", "Perfume", "Shampoo", "Sunscreen"), IF(B8="Stationery", CHOOSE(RANDBETWEEN(1,5), "Pen", "Notebook", "Marker", "Stapler", "Eraser"), IF(B8="Toys & Games", CHOOSE(RANDBETWEEN(1,5), "Puzzle", "Action Figure", "Board Game", "Doll", "Remote Car"), IF(B8="Sports & Fitness", CHOOSE(RANDBETWEEN(1,5), "Treadmill", "Dumbbells", "Yoga Mat", "Bicycle", "Skipping Rope"), "Unknown")))))))))) -> Moisturizer | D8: 213 | E8: Velocity Retailers
A9: P108 | B9: Sports & Fitness | C9: =IF(B9="Electronics", CHOOSE(RANDBETWEEN(1,5), "Smartphone", "Laptop", "Smartwatch", "Bluetooth Speaker", "Wireless Earbuds"), IF(B9="Clothing", CHOOSE(RANDBETWEEN(1,5), "T-shirt", "Jeans", "Jacket", "Hoodie", "Shorts"), IF(B9="Books", CHOOSE(RANDBETWEEN(1,5), "Novel", "Biography", "Comics", "Cookbook", "Textbook"), IF(B9="Footwear", CHOOSE(RANDBETWEEN(1,5), "Sneakers", "Sandals", "Boots", "Loafers", "Flip-flops"), IF(B9="Furniture", CHOOSE(RANDBETWEEN(1,5), "Chair", "Table", "Sofa", "Wardrobe", "Bed"), IF(B9="Home Appliances", CHOOSE(RANDBETWEEN(1,5), "Refrigerator", "Microwave", "Washing Machine", "Air Conditioner", "Vacuum Cleaner"), IF(B9="Beauty & Personal Care", CHOOSE(RANDBETWEEN(1,5), "Lipstick", "Moisturizer", "Perfume", "Shampoo", "Sunscreen"), IF(B9="Stationery", CHOOSE(RANDBETWEEN(1,5), "Pen", "Notebook", "Marker", "Stapler", "Eraser"), IF(B9="Toys & Games", CHOOSE(RANDBETWEEN(1,5), "Puzzle", "Action Figure", "Board Game", "Doll", "Remote Car"), IF(B9="Sports & Fitness", CHOOSE(RANDBETWEEN(1,5), "Treadmill", "Dumbbells", "Yoga Mat", "Bicycle", "Skipping Rope"), "Unknown")))))))))) -> Bicycle | D9: 117 | E9: SmartBazaar Pvt. Ltd.
A10: P109 | B10: Books | C10: Fiction Novel | D10: 399 | E10: MegaMart Traders
A11: P110 | B11: Home Appliances | C11: =IF(B11="Electronics", CHOOSE(RANDBETWEEN(1,5), "Smartphone", "Laptop", "Smartwatch", "Bluetooth Speaker", "Wireless Earbuds"), IF(B11="Clothing", CHOOSE(RANDBETWEEN(1,5), "T-shirt", "Jeans", "Jacket", "Hoodie", "Shorts"), IF(B11="Books", CHOOSE(RANDBETWEEN(1,5), "Novel", "Biography", "Comics", "Cookbook", "Textbook"), IF(B11="Footwear", CHOOSE(RANDBETWEEN(1,5), "Sneakers", "Sandals", "Boots", "Loafers", "Flip-flops"), IF(B11="Furniture", CHOOSE(RANDBETWEEN(1,5), "Chair", "Table", "Sofa", "Wardrobe", "Bed"), IF(B11="Home Appliances", CHOOSE(RANDBETWEEN(1,5), "Refrigerator", "Microwave", "Washing Machine", "Air Conditioner", "Vacuum Cleaner"), IF(B11="Beauty & Personal Care", CHOOSE(RANDBETWEEN(1,5), "Lipstick", "Moisturizer", "Perfume", "Shampoo", "Sunscreen"), IF(B11="Stationery", CHOOSE(RANDBETWEEN(1,5), "Pen", "Notebook", "Marker", "Stapler", "Eraser"), IF(B11="Toys & Games", CHOOSE(RANDBETWEEN(1,5), "Puzzle", "Action Figure", "Board Game", "Doll", "Remote Car"), IF(B11="Sports & Fitness", CHOOSE(RANDBETWEEN(1,5), "Treadmill", "Dumbbells", "Yoga Mat", "Bicycle", "Skipping Rope"), "Unknown")))))))))) -> Air Conditioner | D11: 520 | E11: Orion Home Supplies
A12: P111 | B12: Home Appliances | C12: =IF(B12="Electronics", CHOOSE(RANDBETWEEN(1,5), "Smartphone", "Laptop", "Smartwatch", "Bluetooth Speaker", "Wireless Earbuds"), IF(B12="Clothing", CHOOSE(RANDBETWEEN(1,5), "T-shirt", "Jeans", "Jacket", "Hoodie", "Shorts"), IF(B12="Books", CHOOSE(RANDBETWEEN(1,5), "Novel", "Biography", "Comics", "Cookbook", "Textbook"), IF(B12="Footwear", CHOOSE(RANDBETWEEN(1,5), "Sneakers", "Sandals", "Boots", "Loafers", "Flip-flops"), IF(B12="Furniture", CHOOSE(RANDBETWEEN(1,5), "Chair", "Table", "Sofa", "Wardrobe", "Bed"), IF(B12="Home Appliances", CHOOSE(RANDBETWEEN(1,5), "Refrigerator", "Microwave", "Washing Machine", "Air Conditioner", "Vacuum Cleaner"), IF(B12="Beauty & Personal Care", CHOOSE(RANDBETWEEN(1,5), "Lipstick", "Moisturizer", "Perfume", "Shampoo", "Sunscreen"), IF(B12="Stationery", CHOOSE(RANDBETWEEN(1,5), "Pen", "Notebook", "Marker", "Stapler", "Eraser"), IF(B12="Toys & Games", CHOOSE(RANDBETWEEN(1,5), "Puzzle", "Action Figure", "Board Game", "Doll", "Remote Car"), IF(B12="Sports & Fitness", CHOOSE(RANDBETWEEN(1,5), "Treadmill", "Dumbbells", "Yoga Mat", "Bicycle", "Skipping Rope"), "Unknown")))))))))) -> Vacuum Cleaner | D12: 505 | E12: ValueMax Traders
A13: P112 | B13: Clothing | C13: =IF(B13="Electronics", CHOOSE(RANDBETWEEN(1,5), "Smartphone", "Laptop", "Smartwatch", "Bluetooth Speaker", "Wireless Earbuds"), IF(B13="Clothing", CHOOSE(RANDBETWEEN(1,5), "T-shirt", "Jeans", "Jacket", "Hoodie", "Shorts"), IF(B13="Books", CHOOSE(RANDBETWEEN(1,5), "Novel", "Biography", "Comics", "Cookbook", "Textbook"), IF(B13="Footwear", CHOOSE(RANDBETWEEN(1,5), "Sneakers", "Sandals", "Boots", "Loafers", "Flip-flops"), IF(B13="Furniture", CHOOSE(RANDBETWEEN(1,5), "Chair", "Table", "Sofa", "Wardrobe", "Bed"), IF(B13="Home Appliances", CHOOSE(RANDBETWEEN(1,5), "Refrigerator", "Microwave", "Washing Machine", "Air Conditioner", "Vacuum Cleaner"), IF(B13="Beauty & Personal Care", CHOOSE(RANDBETWEEN(1,5), "Lipstick", "Moisturizer", "Perfume", "Shampoo", "Sunscreen"), IF(B13="Stationery", CHOOSE(RANDBETWEEN(1,5), "Pen", "Notebook", "Marker", "Stapler", "Eraser"), IF(B13="Toys & Games", CHOOSE(RANDBETWEEN(1,5), "Puzzle", "Action Figure", "Board Game", "Doll", "Remote Car"), IF(B13="Sports & Fitness", CHOOSE(RANDBETWEEN(1,5), "Treadmill", "Dumbbells", "Yoga Mat", "Bicycle", "Skipping Rope"), "Unknown")))))))))) -> Jeans | D13: 380 | E13: Velocity Retailers
A14: P113 | B14: Clothing | C14: =IF(B14="Electronics", CHOOSE(RANDBETWEEN(1,5), "Smartphone", "Laptop", "Smartwatch", "Bluetooth Speaker", "Wireless Earbuds"), IF(B14="Clothing", CHOOSE(RANDBETWEEN(1,5), "T-shirt", "Jeans", "Jacket", "Hoodie", "Shorts"), IF(B14="Books", CHOOSE(RANDBETWEEN(1,5), "Novel", "Biography", "Comics", "Cookbook", "Textbook"), IF(B14="Footwear", CHOOSE(RANDBETWEEN(1,5), "Sneakers", "Sandals", "Boots", "Loafers", "Flip-flops"), IF(B14="Furniture", CHOOSE(RANDBETWEEN(1,5), "Chair", "Table", "Sofa", "Wardrobe", "Bed"), IF(B14="Home Appliances", CHOOSE(RANDBETWEEN(1,5), "Refrigerator", "Microwave", "Washing Machine", "Air Conditioner", "Vacuum Cleaner"), IF(B14="Beauty & Personal Care", CHOOSE(RANDBETWEEN(1,5), "Lipstick", "Moisturizer", "Perfume", "Shampoo", "Sunscreen"), IF(B14="Stationery", CHOOSE(RANDBETWEEN(1,5), "Pen", "Notebook", "Marker", "Stapler", "Eraser"), IF(B14="Toys & Games", CHOOSE(RANDBETWEEN(1,5), "Puzzle", "Action Figure", "Board Game", "Doll", "Remote Car"), IF(B14="Sports & Fitness", CHOOSE(RANDBETWEEN(1,5), "Treadmill", "Dumbbells", "Yoga Mat", "Bicycle", "Skipping Rope"), "Unknown")))))))))) -> T-shirt | D14: 392 | E14: Visionary Retailers
A15: P114 | B15: Beauty & Personal Care | C15: Shampoo | D15: 164 | E15: CraftNova Supplies
A16: P115 | B16: Sports & Fitness | C16: =IF(B16="Electronics", CHOOSE(RANDBETWEEN(1,5), "Smartphone", "Laptop", "Smartwatch", "Bluetooth Speaker", "Wireless Earbuds"), IF(B16="Clothing", CHOOSE(RANDBETWEEN(1,5), "T-shirt", "Jeans", "Jacket", "Hoodie", "Shorts"), IF(B16="Books", CHOOSE(RANDBETWEEN(1,5), "Novel", "Biography", "Comics", "Cookbook", "Textbook"), IF(B16="Footwear", CHOOSE(RANDBETWEEN(1,5), "Sneakers", "Sandals", "Boots", "Loafers", "Flip-flops"), IF(B16="Furniture", CHOOSE(RANDBETWEEN(1,5), "Chair", "Table", "Sofa", "Wardrobe", "Bed"), IF(B16="Home Appliances", CHOOSE(RANDBETWEEN(1,5), "Refrigerator", "Microwave", "Washing Machine", "Air Conditioner", "Vacuum Cleaner"), IF(B16="Beauty & Personal Care", CHOOSE(RANDBETWEEN(1,5), "Lipstick", "Moisturizer", "Perfume", "Shampoo", "Sunscreen"), IF(B16="Stationery", CHOOSE(RANDBETWEEN(1,5), "Pen", "Notebook", "Marker", "Stapler", "Eraser"), IF(B16="Toys & Games", CHOOSE(RANDBETWEEN(1,5), "Puzzle", "Action Figure", "Board Game", "Doll", "Remote Car"), IF(B16="Sports & Fitness", CHOOSE(RANDBETWEEN(1,5), "Treadmill", "Dumbbells", "Yoga Mat", "Bicycle", "Skipping Rope"), "Unknown")))))))))) -> Treadmill | D16: 282 | E16: ProGear Supply Co.
A17: P116 | B17: Footwear | C17: =IF(B17="Electronics", CHOOSE(RANDBETWEEN(1,5), "Smartphone", "Laptop", "Smartwatch", "Bluetooth Speaker", "Wireless Earbuds"), IF(B17="Clothing", CHOOSE(RANDBETWEEN(1,5), "T-shirt", "Jeans", "Jacket", "Hoodie", "Shorts"), IF(B17="Books", CHOOSE(RANDBETWEEN(1,5), "Novel", "Biography", "Comics", "Cookbook", "Textbook"), IF(B17="Footwear", CHOOSE(RANDBETWEEN(1,5), "Sneakers", "Sandals", "Boots", "Loafers", "Flip-flops"), IF(B17="Furniture", CHOOSE(RANDBETWEEN(1,5), "Chair", "Table", "Sofa", "Wardrobe", "Bed"), IF(B17="Home Appliances", CHOOSE(RANDBETWEEN(1,5), "Refrigerator", "Microwave", "Washing Machine", "Air Conditioner", "Vacuum Cleaner"), IF(B17="Beauty & Personal Care", CHOOSE(RANDBETWEEN(1,5), "Lipstick", "Moisturizer", "Perfume", "Shampoo", "Sunscreen"), IF(B17="Stationery", CHOOSE(RANDBETWEEN(1,5), "Pen", "Notebook", "Marker", "Stapler", "Eraser"), IF(B17="Toys & Games", CHOOSE(RANDBETWEEN(1,5), "Puzzle", "Action Figure", "Board Game", "Doll", "Remote Car"), IF(B17="Sports & Fitness", CHOOSE(RANDBETWEEN(1,5), "Treadmill", "Dumbbells", "Yoga Mat", "Bicycle", "Skipping Rope"), "Unknown")))))))))) -> Sneakers | D17: 386 | E17: OmniMart Vendors
A18: P117 | B18: Footwear | C18: Heels | D18: 217 | E18: Velocity Retailers
